Workbook

Sheet Tableau_de_bord
B1: Modulations numériques — générateur de signaux
B2: Cellules jaunes = paramètres à modifier. Tout le reste se recalcule.
B3: ENTRÉES
B4: Modulation | C4: 16-QAM
B5: Message à transmettre | C5: 25/12
B6: Codage source | C6: ASCII (8 bits/caractère)
B7: Cycles de porteuse par bit | C7: 2
B8: Protocole (16-QAM uniquement) | C8: IEEE 802.11 (Wi-Fi)
B9: RÉSULTATS
B10: Bits par symbole k | C10: =Constellations!F6
B11: Ordre de modulation M = 2^k | C11: =2^C10
B12: Nombre de bits utiles | C12: =Bits!E3
B13: Bits de bourrage (0) | C13: =C14*C10-C12
B14: Nombre de symboles | C14: =IF(C12=0,0,ROUNDUP(C12/C10,0))
B15: Facteur de normalisation (Es = 1) | C15: =Constellations!F9
B16: Durée du message (en Tb) | C16: =C14*C10
B17: Échantillons par cycle de porteuse | C17: =IF(C16=0,0,2000/(C16*C7))
B19: Train binaire (groupé par symbole)
B20: =Symboles!K101
B22: Suite des symboles (valeurs décimales)
B23: =Symboles!L101
B26: Contrôle
B27: =IF(LEN(C5)=0,"⚠ Saisir un message",IF(AND(Bits!B6<>3,LEN(C5)>12),"⚠ Message tronqué à 12 caractères",IF(AND(Bits!B6=2,Bits!B7=0),"⚠ BCD : aucun chiffre dans le message",IF(AND(Bits!B6=3,Bits!E4>0),"⚠ Binaire : "&Bits!E4&" caractère(s) non binaire(s) lus comme 0",IF(AND(Bits!B6=3,LEN(Bits!B8)>96),"⚠ Binaire : tronqué à 96 bits",IF(C17<8,"⚠ Trop peu d'échantillons par cycle : réduire les cycles/bit","✔ OK — "&C12&" bits → "&C14&" symboles "&C4&IF(C4="16-QAM"," — "&C8,"")))))))
B30: MAPPING DES SYMBOLES ÉMIS
B31: Valeur | C31: Bits | D31: I brut | E31: Q brut
B32: =IF(Constellations!N14<Constellations!$F$7,Constellations!N14,"") | C32: =Constellations!O14 | D32: =IF(B32="","",Constellations!P14) | E32: =IF(B32="","",Constellations!Q14)
B33: =IF(Constellations!N15<Constellations!$F$7,Constellations!N15,"") | C33: =Constellations!O15 | D33: =IF(B33="","",Constellations!P15) | E33: =IF(B33="","",Constellations!Q15)
B34: =IF(Constellations!N16<Constellations!$F$7,Constellations!N16,"") | C34: =Constellations!O16 | D34: =IF(B34="","",Constellations!P16) | E34: =IF(B34="","",Constellations!Q16)
B35: =IF(Constellations!N17<Constellations!$F$7,Constellations!N17,"") | C35: =Constellations!O17 | D35: =IF(B35="","",Constellations!P17) | E35: =IF(B35="","",Constellations!Q17)
B36: =IF(Constellations!N18<Constellations!$F$7,Constellations!N18,"") | C36: =Constellations!O18 | D36: =IF(B36="","",Constellations!P18) | E36: =IF(B36="","",Constellations!Q18)
B37: =IF(Constellations!N19<Constellations!$F$7,Constellations!N19,"") | C37: =Constellations!O19 | D37: =IF(B37="","",Constellations!P19) | E37: =IF(B37="","",Constellations!Q19)
B38: =IF(Constellations!N20<Constellations!$F$7,Constellations!N20,"") | C38: =Constellations!O20 | D38: =IF(B38="","",Constellations!P20) | E38: =IF(B38="","",Constellations!Q20)
B39: =IF(Constellations!N21<Constellations!$F$7,Constellations!N21,"") | C39: =Constellations!O21 | D39: =IF(B39="","",Constellations!P21) | E39: =IF(B39="","",Constellations!Q21)
B40: =IF(Constellations!N22<Constellations!$F$7,Constellations!N22,"") | C40: =Constellations!O22 | D40: =IF(B40="","",Constellations!P22) | E40: =IF(B40="","",Constellations!Q22)
B41: =IF(Constellations!N23<Constellations!$F$7,Constellations!N23,"") | C41: =Constellations!O23 | D41: =IF(B41="","",Constellations!P23) | E41: =IF(B41="","",Constellations!Q23)
B42: =IF(Constellations!N24<Constellations!$F$7,Constellations!N24,"") | C42: =Constellations!O24 | D42: =IF(B42="","",Constellations!P24) | E42: =IF(B42="","",Constellations!Q24)
B43: =IF(Constellations!N25<Constellations!$F$7,Constellations!N25,"") | C43: =Constellations!O25 | D43: =IF(B43="","",Constellations!P25) | E43: =IF(B43="","",Constellations!Q25)
... B49: =IF(Constellations!N31<Constellations!$F$7,Constellations!N31,"") | C49: =Constellations!O31 | D49: =IF(B49="","",Constellations!P31) | E49: =IF(B49="","",Constellations!Q31)
B50: =IF(Constellations!N32<Constellations!$F$7,Constellations!N32,"") | C50: =Constellations!O32 | D50: =IF(B50="","",Constellations!P32) | E50: =IF(B50="","",Constellations!Q32) | G50: DIAGRAMME DE L'ŒIL (bande de base après filtre de mise en forme)
B51: =IF(Constellations!N33<Constellations!$F$7,Constellations!N33,"") | C51: =Constellations!O33 | D51: =IF(B51="","",Constellations!P33) | E51: =IF(B51="","",Constellations!Q33) | G51: Filtre de mise en forme | L51: Cosinus surélevé | P51: Bruit tiré au hasard : appuyer sur F9 pour un nouveau tirage. Échelle normalisée (Es = 1). Astuce : un message plus long (ou le codage Binaire direct) donne un œil plus fourni.
...

Sheet Bits
A1: Codage source : message → bits
K2: Liste des codages
A3: Message | B3: ='Tableau_de_bord'!C5 | D3: Nb bits utiles | E3: =IF(B6=1,8*MIN(B5,12),IF(B6=2,4*B7,MIN(LEN(B8),96))) | L3: ASCII (8 bits/caractère)
A4: Codage | B4: ='Tableau_de_bord'!C6 | D4: Car. non binaires | E4: =LEN(SUBSTITUTE(SUBSTITUTE(B8,"0",""),"1","")) | L4: BCD (4 bits/chiffre)
A5: Longueur (car.) | B5: =LEN(B3) | L5: Binaire direct (0/1)
A6: N° codage | B6: =MATCH(B4,$L$3:$L$5,0)
A7: Nb chiffres (BCD) | B7: =SUM(E10:E21)
A8: Chaîne binaire nettoyée | B8: =SUBSTITUTE(B3," ","")
A9: Position | B9: Caractère | C9: Code ASCII | D9: ASCII binaire (8 b) | E9: Chiffre ? | F9: Cumul chiffres | G9: Chiffre n°i | H9: BCD (4 b)
A10: 1 | B10: =IF(A10<=$B$5,MID($B$3,A10,1),"") | C10: =IF(B10="","",CODE(B10)) | D10: =IF(C10="","",DEC2BIN(MOD(C10,256),8)) | E10: =IF(C10="",0,IF(AND(C10>=48,C10<=57),1,0)) | F10: =SUM(E$10:E10) | G10: =IF(A10<=$B$7,INDEX($C$10:$C$21,MATCH(A10,$F$10:$F$21,0))-48,"") | H10: =IF(G10="","",DEC2BIN(G10,4))
A11: 2 | B11: =IF(A11<=$B$5,MID($B$3,A11,1),"") | C11: =IF(B11="","",CODE(B11)) | D11: =IF(C11="","",DEC2BIN(MOD(C11,256),8)) | E11: =IF(C11="",0,IF(AND(C11>=48,C11<=57),1,0)) | F11: =SUM(E$10:E11) | G11: =IF(A11<=$B$7,INDEX($C$10:$C$21,MATCH(A11,$F$10:$F$21,0))-48,"") | H11: =IF(G11="","",DEC2BIN(G11,4))
A12: 3 | B12: =IF(A12<=$B$5,MID($B$3,A12,1),"") | C12: =IF(B12="","",CODE(B12)) | D12: =IF(C12="","",DEC2BIN(MOD(C12,256),8)) | E12: =IF(C12="",0,IF(AND(C12>=48,C12<=57),1,0)) | F12: =SUM(E$10:E12) | G12: =IF(A12<=$B$7,INDEX($C$10:$C$21,MATCH(A12,$F$10:$F$21,0))-48,"") | H12: =IF(G12="","",DEC2BIN(G12,4))
A13: 4 | B13: =IF(A13<=$B$5,MID($B$3,A13,1),"") | C13: =IF(B13="","",CODE(B13)) | D13: =IF(C13="","",DEC2BIN(MOD(C13,256),8)) | E13: =IF(C13="",0,IF(AND(C13>=48,C13<=57),1,0)) | F13: =SUM(E$10:E13) | G13: =IF(A13<=$B$7,INDEX($C$10:$C$21,MATCH(A13,$F$10:$F$21,0))-48,"") | H13: =IF(G13="","",DEC2BIN(G13,4))
A14: 5 | B14: =IF(A14<=$B$5,MID($B$3,A14,1),"") | C14: =IF(B14="","",CODE(B14)) | D14: =IF(C14="","",DEC2BIN(MOD(C14,256),8)) | E14: =IF(C14="",0,IF(AND(C14>=48,C14<=57),1,0)) | F14: =SUM(E$10:E14) | G14: =IF(A14<=$B$7,INDEX($C$10:$C$21,MATCH(A14,$F$10:$F$21,0))-48,"") | H14: =IF(G14="","",DEC2BIN(G14,4))
A15: 6 | B15: =IF(A15<=$B$5,MID($B$3,A15,1),"") | C15: =IF(B15="","",CODE(B15)) | D15: =IF(C15="","",DEC2BIN(MOD(C15,256),8)) | E15: =IF(C15="",0,IF(AND(C15>=48,C15<=57),1,0)) | F15: =SUM(E$10:E15) | G15: =IF(A15<=$B$7,INDEX($C$10:$C$21,MATCH(A15,$F$10:$F$21,0))-48,"") | H15: =IF(G15="","",DEC2BIN(G15,4))
A16: 7 | B16: =IF(A16<=$B$5,MID($B$3,A16,1),"") | C16: =IF(B16="","",CODE(B16)) | D16: =IF(C16="","",DEC2BIN(MOD(C16,256),8)) | E16: =IF(C16="",0,IF(AND(C16>=48,C16<=57),1,0)) | F16: =SUM(E$10:E16) | G16: =IF(A16<=$B$7,INDEX($C$10:$C$21,MATCH(A16,$F$10:$F$21,0))-48,"") | H16: =IF(G16="","",DEC2BIN(G16,4))
A17: 8 | B17: =IF(A17<=$B$5,MID($B$3,A17,1),"") | C17: =IF(B17="","",CODE(B17)) | D17: =IF(C17="","",DEC2BIN(MOD(C17,256),8)) | E17: =IF(C17="",0,IF(AND(C17>=48,C17<=57),1,0)) | F17: =SUM(E$10:E17) | G17: =IF(A17<=$B$7,INDEX($C$10:$C$21,MATCH(A17,$F$10:$F$21,0))-48,"") | H17: =IF(G17="","",DEC2BIN(G17,4))
A18: 9 | B18: =IF(A18<=$B$5,MID($B$3,A18,1),"") | C18: =IF(B18="","",CODE(B18)) | D18: =IF(C18="","",DEC2BIN(MOD(C18,256),8)) | E18: =IF(C18="",0,IF(AND(C18>=48,C18<=57),1,0)) | F18: =SUM(E$10:E18) | G18: =IF(A18<=$B$7,INDEX($C$10:$C$21,MATCH(A18,$F$10:$F$21,0))-48,"") | H18: =IF(G18="","",DEC2BIN(G18,4))
A19: 10 | B19: =IF(A19<=$B$5,MID($B$3,A19,1),"") | C19: =IF(B19="","",CODE(B19)) | D19: =IF(C19="","",DEC2BIN(MOD(C19,256),8)) | E19: =IF(C19="",0,IF(AND(C19>=48,C19<=57),1,0)) | F19: =SUM(E$10:E19) | G19: =IF(A19<=$B$7,INDEX($C$10:$C$21,MATCH(A19,$F$10:$F$21,0))-48,"") | H19: =IF(G19="","",DEC2BIN(G19,4))
A20: 11 | B20: =IF(A20<=$B$5,MID($B$3,A20,1),"") | C20: =IF(B20="","",CODE(B20)) | D20: =IF(C20="","",DEC2BIN(MOD(C20,256),8)) | E20: =IF(C20="",0,IF(AND(C20>=48,C20<=57),1,0)) | F20: =SUM(E$10:E20) | G20: =IF(A20<=$B$7,INDEX($C$10:$C$21,MATCH(A20,$F$10:$F$21,0))-48,"") | H20: =IF(G20="","",DEC2BIN(G20,4))
A21: 12 | B21: =IF(A21<=$B$5,MID($B$3,A21,1),"") | C21: =IF(B21="","",CODE(B21)) | D21: =IF(C21="","",DEC2BIN(MOD(C21,256),8)) | E21: =IF(C21="",0,IF(AND(C21>=48,C21<=57),1,0)) | F21: =SUM(E$10:E21) | G21: =IF(A21<=$B$7,INDEX($C$10:$C$21,MATCH(A21,$F$10:$F$21,0))-48,"") | H21: =IF(G21="","",DEC2BIN(G21,4))
A24: n° bit | B24: bit ASCII | C24: bit BCD | D24: bit binaire | E24: BIT FINAL | F24: Statut
A25: 1 | B25: =IF(A25>96,0,IF(INDEX($C$10:$C$21,INT((A25-1)/8)+1)="",0,MOD(INT(MOD(INDEX($C$10:$C$21,INT((A25-1)/8)+1),256)/2^(7-MOD(A25-1,8))),2))) | C25: =IF(A25>48,0,IF(INDEX($G$10:$G$21,INT((A25-1)/4)+1)="",0,MOD(INT(INDEX($G$10:$G$21,INT((A25-1)/4)+1)/2^(3-MOD(A25-1,4))),2))) | D25: =IF(MID($B$8,A25,1)="1",1,0) | E25: =IF(A25<=$E$3,CHOOSE($B$6,B25,C25,D25),0) | F25: =IF(A25<=$E$3,"donnée",IF(A25<='Tableau_de_bord'!$C$16,"bourrage",""))
A26: 2 | B26: =IF(A26>96,0,IF(INDEX($C$10:$C$21,INT((A26-1)/8)+1)="",0,MOD(INT(MOD(INDEX($C$10:$C$21,INT((A26-1)/8)+1),256)/2^(7-MOD(A26-1,8))),2))) | C26: =IF(A26>48,0,IF(INDEX($G$10:$G$21,INT((A26-1)/4)+1)="",0,MOD(INT(INDEX($G$10:$G$21,INT((A26-1)/4)+1)/2^(3-MOD(A26-1,4))),2))) | D26: =IF(MID($B$8,A26,1)="1",1,0) | E26: =IF(A26<=$E$3,CHOOSE($B$6,B26,C26,D26),0) | F26: =IF(A26<=$E$3,"donnée",IF(A26<='Tableau_de_bord'!$C$16,"bourrage",""))
A27: 3 | B27: =IF(A27>96,0,IF(INDEX($C$10:$C$21,INT((A27-1)/8)+1)="",0,MOD(INT(MOD(INDEX($C$10:$C$21,INT((A27-1)/8)+1),256)/2^(7-MOD(A27-1,8))),2))) | C27: =IF(A27>48,0,IF(INDEX($G$10:$G$21,INT((A27-1)/4)+1)="",0,MOD(INT(INDEX($G$10:$G$21,INT((A27-1)/4)+1)/2^(3-MOD(A27-1,4))),2))) | D27: =IF(MID($B$8,A27,1)="1",1,0) | E27: =IF(A27<=$E$3,CHOOSE($B$6,B27,C27,D27),0) | F27: =IF(A27<=$E$3,"donnée",IF(A27<='Tableau_de_bord'!$C$16,"bourrage",""))
A28: 4 | B28: =IF(A28>96,0,IF(INDEX($C$10:$C$21,INT((A28-1)/8)+1)="",0,MOD(INT(MOD(INDEX($C$10:$C$21,INT((A28-1)/8)+1),256)/2^(7-MOD(A28-1,8))),2))) | C28: =IF(A28>48,0,IF(INDEX($G$10:$G$21,INT((A28-1)/4)+1)="",0,MOD(INT(INDEX($G$10:$G$21,INT((A28-1)/4)+1)/2^(3-MOD(A28-1,4))),2))) | D28: =IF(MID($B$8,A28,1)="1",1,0) | E28: =IF(A28<=$E$3,CHOOSE($B$6,B28,C28,D28),0) | F28: =IF(A28<=$E$3,"donnée",IF(A28<='Tableau_de_bord'!$C$16,"bourrage",""))
A29: 5 | B29: =IF(A29>96,0,IF(INDEX($C$10:$C$21,INT((A29-1)/8)+1)="",0,MOD(INT(MOD(INDEX($C$10:$C$21,INT((A29-1)/8)+1),256)/2^(7-MOD(A29-1,8))),2))) | C29: =IF(A29>48,0,IF(INDEX($G$10:$G$21,INT((A29-1)/4)+1)="",0,MOD(INT(INDEX($G$10:$G$21,INT((A29-1)/4)+1)/2^(3-MOD(A29-1,4))),2))) | D29: =IF(MID($B$8,A29,1)="1",1,0) | E29: =IF(A29<=$E$3,CHOOSE($B$6,B29,C29,D29),0) | F29: =IF(A29<=$E$3,"donnée",IF(A29<='Tableau_de_bord'!$C$16,"bourrage",""))
A30: 6 | B30: =IF(A30>96,0,IF(INDEX($C$10:$C$21,INT((A30-1)/8)+1)="",0,MOD(INT(MOD(INDEX($C$10:$C$21,INT((A30-1)/8)+1),256)/2^(7-MOD(A30-1,8))),2))) | C30: =IF(A30>48,0,IF(INDEX($G$10:$G$21,INT((A30-1)/4)+1)="",0,MOD(INT(INDEX($G$10:$G$21,INT((A30-1)/4)+1)/2^(3-MOD(A30-1,4))),2))) | D30: =IF(MID($B$8,A30,1)="1",1,0) | E30: =IF(A30<=$E$3,CHOOSE($B$6,B30,C30,D30),0) | F30: =IF(A30<=$E$3,"donnée",IF(A30<='Tableau_de_bord'!$C$16,"bourrage",""))
A31: 7 | B31: =IF(A31>96,0,IF(INDEX($C$10:$C$21,INT((A31-1)/8)+1)="",0,MOD(INT(MOD(INDEX($C$10:$C$21,INT((A31-1)/8)+1),256)/2^(7-MOD(A31-1,8))),2))) | C31: =IF(A31>48,0,IF(INDEX($G$10:$G$21,INT((A31-1)/4)+1)="",0,MOD(INT(INDEX($G$10:$G$21,INT((A31-1)/4)+1)/2^(3-MOD(A31-1,4))),2))) | D31: =IF(MID($B$8,A31,1)="1",1,0) | E31: =IF(A31<=$E$3,CHOOSE($B$6,B31,C31,D31),0) | F31: =IF(A31<=$E$3,"donnée",IF(A31<='Tableau_de_bord'!$C$16,"bourrage",""))
A32: 8 | B32: =IF(A32>96,0,IF(INDEX($C$10:$C$21,INT((A32-1)/8)+1)="",0,MOD(INT(MOD(INDEX($C$10:$C$21,INT((A32-1)/8)+1),256)/2^(7-MOD(A32-1,8))),2))) | C32: =IF(A32>48,0,IF(INDEX($G$10:$G$21,INT((A32-1)/4)+1)="",0,MOD(INT(INDEX($G$10:$G$21,INT((A32-1)/4)+1)/2^(3-MOD(A32-1,4))),2))) | D32: =IF(MID($B$8,A32,1)="1",1,0) | E32: =IF(A32<=$E$3,CHOOSE($B$6,B32,C32,D32),0) | F32: =IF(A32<=$E$3,"donnée",IF(A32<='Tableau_de_bord'!$C$16,"bourrage",""))
A33: 9 | B33: =IF(A33>96,0,IF(INDEX($C$10:$C$21,INT((A33-1)/8)+1)="",0,MOD(INT(MOD(INDEX($C$10:$C$21,INT((A33-1)/8)+1),256)/2^(7-MOD(A33-1,8))),2))) | C33: =IF(A33>48,0,IF(INDEX($G$10:$G$21,INT((A33-1)/4)+1)="",0,MOD(INT(INDEX($G$10:$G$21,INT((A33-1)/4)+1)/2^(3-MOD(A33-1,4))),2))) | D33: =IF(MID($B$8,A33,1)="1",1,0) | E33: =IF(A33<=$E$3,CHOOSE($B$6,B33,C33,D33),0) | F33: =IF(A33<=$E$3,"donnée",IF(A33<='Tableau_de_bord'!$C$16,"bourrage",""))
A34: 10 | B34: =IF(A34>96,0,IF(INDEX($C$10:$C$21,INT((A34-1)/8)+1)="",0,MOD(INT(MOD(INDEX($C$10:$C$21,INT((A34-1)/8)+1),256)/2^(7-MOD(A34-1,8))),2))) | C34: =IF(A34>48,0,IF(INDEX($G$10:$G$21,INT((A34-1)/4)+1)="",0,MOD(INT(INDEX($G$10:$G$21,INT((A34-1)/4)+1)/2^(3-MOD(A34-1,4))),2))) | D34: =IF(MID($B$8,A34,1)="1",1,0) | E34: =IF(A34<=$E$3,CHOOSE($B$6,B34,C34,D34),0) | F34: =IF(A34<=$E$3,"donnée",IF(A34<='Tableau_de_bord'!$C$16,"bourrage",""))
A35: 11 | B35: =IF(A35>96,0,IF(INDEX($C$10:$C$21,INT((A35-1)/8)+1)="",0,MOD(INT(MOD(INDEX($C$10:$C$21,INT((A35-1)/8)+1),256)/2^(7-MOD(A35-1,8))),2))) | C35: =IF(A35>48,0,IF(INDEX($G$10:$G$21,INT((A35-1)/4)+1)="",0,MOD(INT(INDEX($G$10:$G$21,INT((A35-1)/4)+1)/2^(3-MOD(A35-1,4))),2))) | D35: =IF(MID($B$8,A35,1)="1",1,0) | E35: =IF(A35<=$E$3,CHOOSE($B$6,B35,C35,D35),0) | F35: =IF(A35<=$E$3,"donnée",IF(A35<='Tableau_de_bord'!$C$16,"bourrage",""))
A36: 12 | B36: =IF(A36>96,0,IF(INDEX($C$10:$C$21,INT((A36-1)/8)+1)="",0,MOD(INT(MOD(INDEX($C$10:$C$21,INT((A36-1)/8)+1),256)/2^(7-MOD(A36-1,8))),2))) | C36: =IF(A36>48,0,IF(INDEX($G$10:$G$21,INT((A36-1)/4)+1)="",0,MOD(INT(INDEX($G$10:$G$21,INT((A36-1)/4)+1)/2^(3-MOD(A36-1,4))),2))) | D36: =IF(MID($B$8,A36,1)="1",1,0) | E36: =IF(A36<=$E$3,CHOOSE($B$6,B36,C36,D36),0) | F36: =IF(A36<=$E$3,"donnée",IF(A36<='Tableau_de_bord'!$C$16,"bourrage",""))
... A124: 100 | B124: =IF(A124>96,0,IF(INDEX($C$10:$C$21,INT((A124-1)/8)+1)="",0,MOD(INT(MOD(INDEX($C$10:$C$21,INT((A124-1)/8)+1),256)/2^(7-MOD(A124-1,8))),2))) | C124: =IF(A124>48,0,IF(INDEX($G$10:$G$21,INT((A124-1)/4)+1)="",0,MOD(INT(INDEX($G$10:$G$21,INT((A124-1)/4)+1)/2^(3-MOD(A124-1,4))),2))) | D124: =IF(MID($B$8,A124,1)="1",1,0) | E124: =IF(A124<=$E$3,CHOOSE($B$6,B124,C124,D124),0) | F124: =IF(A124<=$E$3,"donnée",IF(A124<='Tableau_de_bord'!$C$16,"bourrage",""))

Sheet Symboles
A1: Regroupement des bits en symboles et mapping I/Q
A2: k = | B2: ='Tableau_de_bord'!C10 | C2: Nb symboles = | D2: ='Tableau_de_bord'!C14 | E2: Facteur norm. = | F2: =Constellations!F9
A5: n° symbole | B5: Bits | C5: Valide | D5: Valeur déc. | E5: I brut | F5: Q brut | G5: I norm. | H5: Q norm. | I5: Amplitude | J5: Phase (°) | K5: Train binaire (groupé) | L5: Suite des symboles
A6: 1 | B6: =IF(C6=0,"",IF(0<$B$2,INDEX(Bits!$E$25:$E$124,(A6-1)*$B$2+1),"")&IF(1<$B$2,INDEX(Bits!$E$25:$E$124,(A6-1)*$B$2+2),"")&IF(2<$B$2,INDEX(Bits!$E$25:$E$124,(A6-1)*$B$2+3),"")&IF(3<$B$2,INDEX(Bits!$E$25:$E$124,(A6-1)*$B$2+4),"")&IF(4<$B$2,INDEX(Bits!$E$25:$E$124,(A6-1)*$B$2+5),"")) | C6: =IF(A6<=$D$2,1,0) | D6: =IF(C6=0,"",IF(0<$B$2,INDEX(Bits!$E$25:$E$124,(A6-1)*$B$2+1)*2^($B$2-1),0)+IF(1<$B$2,INDEX(Bits!$E$25:$E$124,(A6-1)*$B$2+2)*2^($B$2-2),0)+IF(2<$B$2,INDEX(Bits!$E$25:$E$124,(A6-1)*$B$2+3)*2^($B$2-3),0)+IF(3<$B$2,INDEX(Bits!$E$25:$E$124,(A6-1)*$B$2+4)*2^($B$2-4),0)+IF(4<$B$2,INDEX(Bits!$E$25:$E$124,(A6-1)*$B$2+5)*2^($B$2-5),0)) | E6: =IF(C6=0,"",INDEX(Constellations!$C$14:$L$45,D6+1,Constellations!$F$8)) | F6: =IF(C6=0,"",INDEX(Constellations!$C$14:$L$45,D6+1,Constellations!$F$8+1)) | G6: =IF(C6=0,"",E6*$F$2) | H6: =IF(C6=0,"",F6*$F$2) | I6: =IF(C6=0,"",SQRT(G6^2+H6^2)) | J6: =IF(C6=0,"",IF(AND(G6=0,H6=0),0,DEGREES(ATAN2(G6,H6)))) | K6: =B6 | L6: =IF(D6="","",D6&"")
A7: 2 | B7: =IF(C7=0,"",IF(0<$B$2,INDEX(Bits!$E$25:$E$124,(A7-1)*$B$2+1),"")&IF(1<$B$2,INDEX(Bits!$E$25:$E$124,(A7-1)*$B$2+2),"")&IF(2<$B$2,INDEX(Bits!$E$25:$E$124,(A7-1)*$B$2+3),"")&IF(3<$B$2,INDEX(Bits!$E$25:$E$124,(A7-1)*$B$2+4),"")&IF(4<$B$2,INDEX(Bits!$E$25:$E$124,(A7-1)*$B$2+5),"")) | C7: =IF(A7<=$D$2,1,0) | D7: =IF(C7=0,"",IF(0<$B$2,INDEX(Bits!$E$25:$E$124,(A7-1)*$B$2+1)*2^($B$2-1),0)+IF(1<$B$2,INDEX(Bits!$E$25:$E$124,(A7-1)*$B$2+2)*2^($B$2-2),0)+IF(2<$B$2,INDEX(Bits!$E$25:$E$124,(A7-1)*$B$2+3)*2^($B$2-3),0)+IF(3<$B$2,INDEX(Bits!$E$25:$E$124,(A7-1)*$B$2+4)*2^($B$2-4),0)+IF(4<$B$2,INDEX(Bits!$E$25:$E$124,(A7-1)*$B$2+5)*2^($B$2-5),0)) | E7: =IF(C7=0,"",INDEX(Constellations!$C$14:$L$45,D7+1,Constellations!$F$8)) | F7: =IF(C7=0,"",INDEX(Constellations!$C$14:$L$45,D7+1,Constellations!$F$8+1)) | G7: =IF(C7=0,"",E7*$F$2) | H7: =IF(C7=0,"",F7*$F$2) | I7: =IF(C7=0,"",SQRT(G7^2+H7^2)) | J7: =IF(C7=0,"",IF(AND(G7=0,H7=0),0,DEGREES(ATAN2(G7,H7)))) | K7: =IF(C7=0,K6,K6&" "&B7) | L7: =IF(C7=0,L6,L6&" - "&D7)
A8: 3 | B8: =IF(C8=0,"",IF(0<$B$2,INDEX(Bits!$E$25:$E$124,(A8-1)*$B$2+1),"")&IF(1<$B$2,INDEX(Bits!$E$25:$E$124,(A8-1)*$B$2+2),"")&IF(2<$B$2,INDEX(Bits!$E$25:$E$124,(A8-1)*$B$2+3),"")&IF(3<$B$2,INDEX(Bits!$E$25:$E$124,(A8-1)*$B$2+4),"")&IF(4<$B$2,INDEX(Bits!$E$25:$E$124,(A8-1)*$B$2+5),"")) | C8: =IF(A8<=$D$2,1,0) | D8: =IF(C8=0,"",IF(0<$B$2,INDEX(Bits!$E$25:$E$124,(A8-1)*$B$2+1)*2^($B$2-1),0)+IF(1<$B$2,INDEX(Bits!$E$25:$E$124,(A8-1)*$B$2+2)*2^($B$2-2),0)+IF(2<$B$2,INDEX(Bits!$E$25:$E$124,(A8-1)*$B$2+3)*2^($B$2-3),0)+IF(3<$B$2,INDEX(Bits!$E$25:$E$124,(A8-1)*$B$2+4)*2^($B$2-4),0)+IF(4<$B$2,INDEX(Bits!$E$25:$E$124,(A8-1)*$B$2+5)*2^($B$2-5),0)) | E8: =IF(C8=0,"",INDEX(Constellations!$C$14:$L$45,D8+1,Constellations!$F$8)) | F8: =IF(C8=0,"",INDEX(Constellations!$C$14:$L$45,D8+1,Constellations!$F$8+1)) | G8: =IF(C8=0,"",E8*$F$2) | H8: =IF(C8=0,"",F8*$F$2) | I8: =IF(C8=0,"",SQRT(G8^2+H8^2)) | J8: =IF(C8=0,"",IF(AND(G8=0,H8=0),0,DEGREES(ATAN2(G8,H8)))) | K8: =IF(C8=0,K7,K7&" "&B8) | L8: =IF(C8=0,L7,L7&" - "&D8)
A9: 4 | B9: =IF(C9=0,"",IF(0<$B$2,INDEX(Bits!$E$25:$E$124,(A9-1)*$B$2+1),"")&IF(1<$B$2,INDEX(Bits!$E$25:$E$124,(A9-1)*$B$2+2),"")&IF(2<$B$2,INDEX(Bits!$E$25:$E$124,(A9-1)*$B$2+3),"")&IF(3<$B$2,INDEX(Bits!$E$25:$E$124,(A9-1)*$B$2+4),"")&IF(4<$B$2,INDEX(Bits!$E$25:$E$124,(A9-1)*$B$2+5),"")) | C9: =IF(A9<=$D$2,1,0) | D9: =IF(C9=0,"",IF(0<$B$2,INDEX(Bits!$E$25:$E$124,(A9-1)*$B$2+1)*2^($B$2-1),0)+IF(1<$B$2,INDEX(Bits!$E$25:$E$124,(A9-1)*$B$2+2)*2^($B$2-2),0)+IF(2<$B$2,INDEX(Bits!$E$25:$E$124,(A9-1)*$B$2+3)*2^($B$2-3),0)+IF(3<$B$2,INDEX(Bits!$E$25:$E$124,(A9-1)*$B$2+4)*2^($B$2-4),0)+IF(4<$B$2,INDEX(Bits!$E$25:$E$124,(A9-1)*$B$2+5)*2^($B$2-5),0)) | E9: =IF(C9=0,"",INDEX(Constellations!$C$14:$L$45,D9+1,Constellations!$F$8)) | F9: =IF(C9=0,"",INDEX(Constellations!$C$14:$L$45,D9+1,Constellations!$F$8+1)) | G9: =IF(C9=0,"",E9*$F$2) | H9: =IF(C9=0,"",F9*$F$2) | I9: =IF(C9=0,"",SQRT(G9^2+H9^2)) | J9: =IF(C9=0,"",IF(AND(G9=0,H9=0),0,DEGREES(ATAN2(G9,H9)))) | K9: =IF(C9=0,K8,K8&" "&B9) | L9: =IF(C9=0,L8,L8&" - "&D9)
A10: 5 | B10: =IF(C10=0,"",IF(0<$B$2,INDEX(Bits!$E$25:$E$124,(A10-1)*$B$2+1),"")&IF(1<$B$2,INDEX(Bits!$E$25:$E$124,(A10-1)*$B$2+2),"")&IF(2<$B$2,INDEX(Bits!$E$25:$E$124,(A10-1)*$B$2+3),"")&IF(3<$B$2,INDEX(Bits!$E$25:$E$124,(A10-1)*$B$2+4),"")&IF(4<$B$2,INDEX(Bits!$E$25:$E$124,(A10-1)*$B$2+5),"")) | C10: =IF(A10<=$D$2,1,0) | D10: =IF(C10=0,"",IF(0<$B$2,INDEX(Bits!$E$25:$E$124,(A10-1)*$B$2+1)*2^($B$2-1),0)+IF(1<$B$2,INDEX(Bits!$E$25:$E$124,(A10-1)*$B$2+2)*2^($B$2-2),0)+IF(2<$B$2,INDEX(Bits!$E$25:$E$124,(A10-1)*$B$2+3)*2^($B$2-3),0)+IF(3<$B$2,INDEX(Bits!$E$25:$E$124,(A10-1)*$B$2+4)*2^($B$2-4),0)+IF(4<$B$2,INDEX(Bits!$E$25:$E$124,(A10-1)*$B$2+5)*2^($B$2-5),0)) | E10: =IF(C10=0,"",INDEX(Constellations!$C$14:$L$45,D10+1,Constellations!$F$8)) | F10: =IF(C10=0,"",INDEX(Constellations!$C$14:$L$45,D10+1,Constellations!$F$8+1)) | G10: =IF(C10=0,"",E10*$F$2) | H10: =IF(C10=0,"",F10*$F$2) | I10: =IF(C10=0,"",SQRT(G10^2+H10^2)) | J10: =IF(C10=0,"",IF(AND(G10=0,H10=0),0,DEGREES(ATAN2(G10,H10)))) | K10: =IF(C10=0,K9,K9&" "&B10) | L10: =IF(C10=0,L9,L9&" - "&D10)
A11: 6 | B11: =IF(C11=0,"",IF(0<$B$2,INDEX(Bits!$E$25:$E$124,(A11-1)*$B$2+1),"")&IF(1<$B$2,INDEX(Bits!$E$25:$E$124,(A11-1)*$B$2+2),"")&IF(2<$B$2,INDEX(Bits!$E$25:$E$124,(A11-1)*$B$2+3),"")&IF(3<$B$2,INDEX(Bits!$E$25:$E$124,(A11-1)*$B$2+4),"")&IF(4<$B$2,INDEX(Bits!$E$25:$E$124,(A11-1)*$B$2+5),"")) | C11: =IF(A11<=$D$2,1,0) | D11: =IF(C11=0,"",IF(0<$B$2,INDEX(Bits!$E$25:$E$124,(A11-1)*$B$2+1)*2^($B$2-1),0)+IF(1<$B$2,INDEX(Bits!$E$25:$E$124,(A11-1)*$B$2+2)*2^($B$2-2),0)+IF(2<$B$2,INDEX(Bits!$E$25:$E$124,(A11-1)*$B$2+3)*2^($B$2-3),0)+IF(3<$B$2,INDEX(Bits!$E$25:$E$124,(A11-1)*$B$2+4)*2^($B$2-4),0)+IF(4<$B$2,INDEX(Bits!$E$25:$E$124,(A11-1)*$B$2+5)*2^($B$2-5),0)) | E11: =IF(C11=0,"",INDEX(Constellations!$C$14:$L$45,D11+1,Constellations!$F$8)) | F11: =IF(C11=0,"",INDEX(Constellations!$C$14:$L$45,D11+1,Constellations!$F$8+1)) | G11: =IF(C11=0,"",E11*$F$2) | H11: =IF(C11=0,"",F11*$F$2) | I11: =IF(C11=0,"",SQRT(G11^2+H11^2)) | J11: =IF(C11=0,"",IF(AND(G11=0,H11=0),0,DEGREES(ATAN2(G11,H11)))) | K11: =IF(C11=0,K10,K10&" "&B11) | L11: =IF(C11=0,L10,L10&" - "&D11)
A12: 7 | B12: =IF(C12=0,"",IF(0<$B$2,INDEX(Bits!$E$25:$E$124,(A12-1)*$B$2+1),"")&IF(1<$B$2,INDEX(Bits!$E$25:$E$124,(A12-1)*$B$2+2),"")&IF(2<$B$2,INDEX(Bits!$E$25:$E$124,(A12-1)*$B$2+3),"")&IF(3<$B$2,INDEX(Bits!$E$25:$E$124,(A12-1)*$B$2+4),"")&IF(4<$B$2,INDEX(Bits!$E$25:$E$124,(A12-1)*$B$2+5),"")) | C12: =IF(A12<=$D$2,1,0) | D12: =IF(C12=0,"",IF(0<$B$2,INDEX(Bits!$E$25:$E$124,(A12-1)*$B$2+1)*2^($B$2-1),0)+IF(1<$B$2,INDEX(Bits!$E$25:$E$124,(A12-1)*$B$2+2)*2^($B$2-2),0)+IF(2<$B$2,INDEX(Bits!$E$25:$E$124,(A12-1)*$B$2+3)*2^($B$2-3),0)+IF(3<$B$2,INDEX(Bits!$E$25:$E$124,(A12-1)*$B$2+4)*2^($B$2-4),0)+IF(4<$B$2,INDEX(Bits!$E$25:$E$124,(A12-1)*$B$2+5)*2^($B$2-5),0)) | E12: =IF(C12=0,"",INDEX(Constellations!$C$14:$L$45,D12+1,Constellations!$F$8)) | F12: =IF(C12=0,"",INDEX(Constellations!$C$14:$L$45,D12+1,Constellations!$F$8+1)) | G12: =IF(C12=0,"",E12*$F$2) | H12: =IF(C12=0,"",F12*$F$2) | I12: =IF(C12=0,"",SQRT(G12^2+H12^2)) | J12: =IF(C12=0,"",IF(AND(G12=0,H12=0),0,DEGREES(ATAN2(G12,H12)))) | K12: =IF(C12=0,K11,K11&" "&B12) | L12: =IF(C12=0,L11,L11&" - "&D12)
A13: 8 | B13: =IF(C13=0,"",IF(0<$B$2,INDEX(Bits!$E$25:$E$124,(A13-1)*$B$2+1),"")&IF(1<$B$2,INDEX(Bits!$E$25:$E$124,(A13-1)*$B$2+2),"")&IF(2<$B$2,INDEX(Bits!$E$25:$E$124,(A13-1)*$B$2+3),"")&IF(3<$B$2,INDEX(Bits!$E$25:$E$124,(A13-1)*$B$2+4),"")&IF(4<$B$2,INDEX(Bits!$E$25:$E$124,(A13-1)*$B$2+5),"")) | C13: =IF(A13<=$D$2,1,0) | D13: =IF(C13=0,"",IF(0<$B$2,INDEX(Bits!$E$25:$E$124,(A13-1)*$B$2+1)*2^($B$2-1),0)+IF(1<$B$2,INDEX(Bits!$E$25:$E$124,(A13-1)*$B$2+2)*2^($B$2-2),0)+IF(2<$B$2,INDEX(Bits!$E$25:$E$124,(A13-1)*$B$2+3)*2^($B$2-3),0)+IF(3<$B$2,INDEX(Bits!$E$25:$E$124,(A13-1)*$B$2+4)*2^($B$2-4),0)+IF(4<$B$2,INDEX(Bits!$E$25:$E$124,(A13-1)*$B$2+5)*2^($B$2-5),0)) | E13: =IF(C13=0,"",INDEX(Constellations!$C$14:$L$45,D13+1,Constellations!$F$8)) | F13: =IF(C13=0,"",INDEX(Constellations!$C$14:$L$45,D13+1,Constellations!$F$8+1)) | G13: =IF(C13=0,"",E13*$F$2) | H13: =IF(C13=0,"",F13*$F$2) | I13: =IF(C13=0,"",SQRT(G13^2+H13^2)) | J13: =IF(C13=0,"",IF(AND(G13=0,H13=0),0,DEGREES(ATAN2(G13,H13)))) | K13: =IF(C13=0,K12,K12&" "&B13) | L13: =IF(C13=0,L12,L12&" - "&D13)
A14: 9 | B14: =IF(C14=0,"",IF(0<$B$2,INDEX(Bits!$E$25:$E$124,(A14-1)*$B$2+1),"")&IF(1<$B$2,INDEX(Bits!$E$25:$E$124,(A14-1)*$B$2+2),"")&IF(2<$B$2,INDEX(Bits!$E$25:$E$124,(A14-1)*$B$2+3),"")&IF(3<$B$2,INDEX(Bits!$E$25:$E$124,(A14-1)*$B$2+4),"")&IF(4<$B$2,INDEX(Bits!$E$25:$E$124,(A14-1)*$B$2+5),"")) | C14: =IF(A14<=$D$2,1,0) | D14: =IF(C14=0,"",IF(0<$B$2,INDEX(Bits!$E$25:$E$124,(A14-1)*$B$2+1)*2^($B$2-1),0)+IF(1<$B$2,INDEX(Bits!$E$25:$E$124,(A14-1)*$B$2+2)*2^($B$2-2),0)+IF(2<$B$2,INDEX(Bits!$E$25:$E$124,(A14-1)*$B$2+3)*2^($B$2-3),0)+IF(3<$B$2,INDEX(Bits!$E$25:$E$124,(A14-1)*$B$2+4)*2^($B$2-4),0)+IF(4<$B$2,INDEX(Bits!$E$25:$E$124,(A14-1)*$B$2+5)*2^($B$2-5),0)) | E14: =IF(C14=0,"",INDEX(Constellations!$C$14:$L$45,D14+1,Constellations!$F$8)) | F14: =IF(C14=0,"",INDEX(Constellations!$C$14:$L$45,D14+1,Constellations!$F$8+1)) | G14: =IF(C14=0,"",E14*$F$2) | H14: =IF(C14=0,"",F14*$F$2) | I14: =IF(C14=0,"",SQRT(G14^2+H14^2)) | J14: =IF(C14=0,"",IF(AND(G14=0,H14=0),0,DEGREES(ATAN2(G14,H14)))) | K14: =IF(C14=0,K13,K13&" "&B14) | L14: =IF(C14=0,L13,L13&" - "&D14)
A15: 10 | B15: =IF(C15=0,"",IF(0<$B$2,INDEX(Bits!$E$25:$E$124,(A15-1)*$B$2+1),"")&IF(1<$B$2,INDEX(Bits!$E$25:$E$124,(A15-1)*$B$2+2),"")&IF(2<$B$2,INDEX(Bits!$E$25:$E$124,(A15-1)*$B$2+3),"")&IF(3<$B$2,INDEX(Bits!$E$25:$E$124,(A15-1)*$B$2+4),"")&IF(4<$B$2,INDEX(Bits!$E$25:$E$124,(A15-1)*$B$2+5),"")) | C15: =IF(A15<=$D$2,1,0) | D15: =IF(C15=0,"",IF(0<$B$2,INDEX(Bits!$E$25:$E$124,(A15-1)*$B$2+1)*2^($B$2-1),0)+IF(1<$B$2,INDEX(Bits!$E$25:$E$124,(A15-1)*$B$2+2)*2^($B$2-2),0)+IF(2<$B$2,INDEX(Bits!$E$25:$E$124,(A15-1)*$B$2+3)*2^($B$2-3),0)+IF(3<$B$2,INDEX(Bits!$E$25:$E$124,(A15-1)*$B$2+4)*2^($B$2-4),0)+IF(4<$B$2,INDEX(Bits!$E$25:$E$124,(A15-1)*$B$2+5)*2^($B$2-5),0)) | E15: =IF(C15=0,"",INDEX(Constellations!$C$14:$L$45,D15+1,Constellations!$F$8)) | F15: =IF(C15=0,"",INDEX(Constellations!$C$14:$L$45,D15+1,Constellations!$F$8+1)) | G15: =IF(C15=0,"",E15*$F$2) | H15: =IF(C15=0,"",F15*$F$2) | I15: =IF(C15=0,"",SQRT(G15^2+H15^2)) | J15: =IF(C15=0,"",IF(AND(G15=0,H15=0),0,DEGREES(ATAN2(G15,H15)))) | K15: =IF(C15=0,K14,K14&" "&B15) | L15: =IF(C15=0,L14,L14&" - "&D15)
A16: 11 | B16: =IF(C16=0,"",IF(0<$B$2,INDEX(Bits!$E$25:$E$124,(A16-1)*$B$2+1),"")&IF(1<$B$2,INDEX(Bits!$E$25:$E$124,(A16-1)*$B$2+2),"")&IF(2<$B$2,INDEX(Bits!$E$25:$E$124,(A16-1)*$B$2+3),"")&IF(3<$B$2,INDEX(Bits!$E$25:$E$124,(A16-1)*$B$2+4),"")&IF(4<$B$2,INDEX(Bits!$E$25:$E$124,(A16-1)*$B$2+5),"")) | C16: =IF(A16<=$D$2,1,0) | D16: =IF(C16=0,"",IF(0<$B$2,INDEX(Bits!$E$25:$E$124,(A16-1)*$B$2+1)*2^($B$2-1),0)+IF(1<$B$2,INDEX(Bits!$E$25:$E$124,(A16-1)*$B$2+2)*2^($B$2-2),0)+IF(2<$B$2,INDEX(Bits!$E$25:$E$124,(A16-1)*$B$2+3)*2^($B$2-3),0)+IF(3<$B$2,INDEX(Bits!$E$25:$E$124,(A16-1)*$B$2+4)*2^($B$2-4),0)+IF(4<$B$2,INDEX(Bits!$E$25:$E$124,(A16-1)*$B$2+5)*2^($B$2-5),0)) | E16: =IF(C16=0,"",INDEX(Constellations!$C$14:$L$45,D16+1,Constellations!$F$8)) | F16: =IF(C16=0,"",INDEX(Constellations!$C$14:$L$45,D16+1,Constellations!$F$8+1)) | G16: =IF(C16=0,"",E16*$F$2) | H16: =IF(C16=0,"",F16*$F$2) | I16: =IF(C16=0,"",SQRT(G16^2+H16^2)) | J16: =IF(C16=0,"",IF(AND(G16=0,H16=0),0,DEGREES(ATAN2(G16,H16)))) | K16: =IF(C16=0,K15,K15&" "&B16) | L16: =IF(C16=0,L15,L15&" - "&D16)
A17: 12 | B17: =IF(C17=0,"",IF(0<$B$2,INDEX(Bits!$E$25:$E$124,(A17-1)*$B$2+1),"")&IF(1<$B$2,INDEX(Bits!$E$25:$E$124,(A17-1)*$B$2+2),"")&IF(2<$B$2,INDEX(Bits!$E$25:$E$124,(A17-1)*$B$2+3),"")&IF(3<$B$2,INDEX(Bits!$E$25:$E$124,(A17-1)*$B$2+4),"")&IF(4<$B$2,INDEX(Bits!$E$25:$E$124,(A17-1)*$B$2+5),"")) | C17: =IF(A17<=$D$2,1,0) | D17: =IF(C17=0,"",IF(0<$B$2,INDEX(Bits!$E$25:$E$124,(A17-1)*$B$2+1)*2^($B$2-1),0)+IF(1<$B$2,INDEX(Bits!$E$25:$E$124,(A17-1)*$B$2+2)*2^($B$2-2),0)+IF(2<$B$2,INDEX(Bits!$E$25:$E$124,(A17-1)*$B$2+3)*2^($B$2-3),0)+IF(3<$B$2,INDEX(Bits!$E$25:$E$124,(A17-1)*$B$2+4)*2^($B$2-4),0)+IF(4<$B$2,INDEX(Bits!$E$25:$E$124,(A17-1)*$B$2+5)*2^($B$2-5),0)) | E17: =IF(C17=0,"",INDEX(Constellations!$C$14:$L$45,D17+1,Constellations!$F$8)) | F17: =IF(C17=0,"",INDEX(Constellations!$C$14:$L$45,D17+1,Constellations!$F$8+1)) | G17: =IF(C17=0,"",E17*$F$2) | H17: =IF(C17=0,"",F17*$F$2) | I17: =IF(C17=0,"",SQRT(G17^2+H17^2)) | J17: =IF(C17=0,"",IF(AND(G17=0,H17=0),0,DEGREES(ATAN2(G17,H17)))) | K17: =IF(C17=0,K16,K16&" "&B17) | L17: =IF(C17=0,L16,L16&" - "&D17)
A18: 13 | B18: =IF(C18=0,"",IF(0<$B$2,INDEX(Bits!$E$25:$E$124,(A18-1)*$B$2+1),"")&IF(1<$B$2,INDEX(Bits!$E$25:$E$124,(A18-1)*$B$2+2),"")&IF(2<$B$2,INDEX(Bits!$E$25:$E$124,(A18-1)*$B$2+3),"")&IF(3<$B$2,INDEX(Bits!$E$25:$E$124,(A18-1)*$B$2+4),"")&IF(4<$B$2,INDEX(Bits!$E$25:$E$124,(A18-1)*$B$2+5),"")) | C18: =IF(A18<=$D$2,1,0) | D18: =IF(C18=0,"",IF(0<$B$2,INDEX(Bits!$E$25:$E$124,(A18-1)*$B$2+1)*2^($B$2-1),0)+IF(1<$B$2,INDEX(Bits!$E$25:$E$124,(A18-1)*$B$2+2)*2^($B$2-2),0)+IF(2<$B$2,INDEX(Bits!$E$25:$E$124,(A18-1)*$B$2+3)*2^($B$2-3),0)+IF(3<$B$2,INDEX(Bits!$E$25:$E$124,(A18-1)*$B$2+4)*2^($B$2-4),0)+IF(4<$B$2,INDEX(Bits!$E$25:$E$124,(A18-1)*$B$2+5)*2^($B$2-5),0)) | E18: =IF(C18=0,"",INDEX(Constellations!$C$14:$L$45,D18+1,Constellations!$F$8)) | F18: =IF(C18=0,"",INDEX(Constellations!$C$14:$L$45,D18+1,Constellations!$F$8+1)) | G18: =IF(C18=0,"",E18*$F$2) | H18: =IF(C18=0,"",F18*$F$2) | I18: =IF(C18=0,"",SQRT(G18^2+H18^2)) | J18: =IF(C18=0,"",IF(AND(G18=0,H18=0),0,DEGREES(ATAN2(G18,H18)))) | K18: =IF(C18=0,K17,K17&" "&B18) | L18: =IF(C18=0,L17,L17&" - "&D18)
... A101: 96 | B101: =IF(C101=0,"",IF(0<$B$2,INDEX(Bits!$E$25:$E$124,(A101-1)*$B$2+1),"")&IF(1<$B$2,INDEX(Bits!$E$25:$E$124,(A101-1)*$B$2+2),"")&IF(2<$B$2,INDEX(Bits!$E$25:$E$124,(A101-1)*$B$2+3),"")&IF(3<$B$2,INDEX(Bits!$E$25:$E$124,(A101-1)*$B$2+4),"")&IF(4<$B$2,INDEX(Bits!$E$25:$E$124,(A101-1)*$B$2+5),"")) | C101: =IF(A101<=$D$2,1,0) | D101: =IF(C101=0,"",IF(0<$B$2,INDEX(Bits!$E$25:$E$124,(A101-1)*$B$2+1)*2^($B$2-1),0)+IF(1<$B$2,INDEX(Bits!$E$25:$E$124,(A101-1)*$B$2+2)*2^($B$2-2),0)+IF(2<$B$2,INDEX(Bits!$E$25:$E$124,(A101-1)*$B$2+3)*2^($B$2-3),0)+IF(3<$B$2,INDEX(Bits!$E$25:$E$124,(A101-1)*$B$2+4)*2^($B$2-4),0)+IF(4<$B$2,INDEX(Bits!$E$25:$E$124,(A101-1)*$B$2+5)*2^($B$2-5),0)) | E101: =IF(C101=0,"",INDEX(Constellations!$C$14:$L$45,D101+1,Constellations!$F$8)) | F101: =IF(C101=0,"",INDEX(Constellations!$C$14:$L$45,D101+1,Constellations!$F$8+1)) | G101: =IF(C101=0,"",E101*$F$2) | H101: =IF(C101=0,"",F101*$F$2) | I101: =IF(C101=0,"",SQRT(G101^2+H101^2)) | J101: =IF(C101=0,"",IF(AND(G101=0,H101=0),0,DEGREES(ATAN2(G101,H101)))) | K101: =IF(C101=0,K100,K100&" "&B101) | L101: =IF(C101=0,L100,L100&" - "&D101)

Sheet Signal
A1: Signal modulé s(t) = I(t)·cos(2π·fc·t) + Q(t)·sin(2π·fc·t)
A2: Durée totale (Tb) | C2: ='Tableau_de_bord'!C16 | E2: Temps exprimé en durées de bit Tb (débit binaire constant) : un symbole dure k·Tb.
A3: Cycles de porteuse / bit | C3: ='Tableau_de_bord'!C7 | E3: 2000 échantillons répartis sur toute la durée du message.
A4: k | C4: ='Tableau_de_bord'!C10
A5: Nb symboles | C5: ='Tableau_de_bord'!C14
A7: n | B7: t (en Tb) | C7: Bit | D7: n° symbole | E7: I(t) | F7: Q(t) | G7: cos(2πfc t) | H7: sin(2πfc t) | I7: s(t)
A8: 1 | B8: =(A8-1)/2000*$C$2 | C8: =INDEX(Bits!$E$25:$E$124,INT(B8)+1) | D8: =MAX(1,MIN(INT(B8/$C$4)+1,$C$5)) | E8: =IF($C$5=0,0,INDEX(Symboles!$G$6:$G$101,D8)) | F8: =IF($C$5=0,0,INDEX(Symboles!$H$6:$H$101,D8)) | G8: =COS(2*PI()*$C$3*B8) | H8: =SIN(2*PI()*$C$3*B8) | I8: =E8*G8+F8*H8
A9: 2 | B9: =(A9-1)/2000*$C$2 | C9: =INDEX(Bits!$E$25:$E$124,INT(B9)+1) | D9: =MAX(1,MIN(INT(B9/$C$4)+1,$C$5)) | E9: =IF($C$5=0,0,INDEX(Symboles!$G$6:$G$101,D9)) | F9: =IF($C$5=0,0,INDEX(Symboles!$H$6:$H$101,D9)) | G9: =COS(2*PI()*$C$3*B9) | H9: =SIN(2*PI()*$C$3*B9) | I9: =E9*G9+F9*H9
A10: 3 | B10: =(A10-1)/2000*$C$2 | C10: =INDEX(Bits!$E$25:$E$124,INT(B10)+1) | D10: =MAX(1,MIN(INT(B10/$C$4)+1,$C$5)) | E10: =IF($C$5=0,0,INDEX(Symboles!$G$6:$G$101,D10)) | F10: =IF($C$5=0,0,INDEX(Symboles!$H$6:$H$101,D10)) | G10: =COS(2*PI()*$C$3*B10) | H10: =SIN(2*PI()*$C$3*B10) | I10: =E10*G10+F10*H10
A11: 4 | B11: =(A11-1)/2000*$C$2 | C11: =INDEX(Bits!$E$25:$E$124,INT(B11)+1) | D11: =MAX(1,MIN(INT(B11/$C$4)+1,$C$5)) | E11: =IF($C$5=0,0,INDEX(Symboles!$G$6:$G$101,D11)) | F11: =IF($C$5=0,0,INDEX(Symboles!$H$6:$H$101,D11)) | G11: =COS(2*PI()*$C$3*B11) | H11: =SIN(2*PI()*$C$3*B11) | I11: =E11*G11+F11*H11
A12: 5 | B12: =(A12-1)/2000*$C$2 | C12: =INDEX(Bits!$E$25:$E$124,INT(B12)+1) | D12: =MAX(1,MIN(INT(B12/$C$4)+1,$C$5)) | E12: =IF($C$5=0,0,INDEX(Symboles!$G$6:$G$101,D12)) | F12: =IF($C$5=0,0,INDEX(Symboles!$H$6:$H$101,D12)) | G12: =COS(2*PI()*$C$3*B12) | H12: =SIN(2*PI()*$C$3*B12) | I12: =E12*G12+F12*H12
A13: 6 | B13: =(A13-1)/2000*$C$2 | C13: =INDEX(Bits!$E$25:$E$124,INT(B13)+1) | D13: =MAX(1,MIN(INT(B13/$C$4)+1,$C$5)) | E13: =IF($C$5=0,0,INDEX(Symboles!$G$6:$G$101,D13)) | F13: =IF($C$5=0,0,INDEX(Symboles!$H$6:$H$101,D13)) | G13: =COS(2*PI()*$C$3*B13) | H13: =SIN(2*PI()*$C$3*B13) | I13: =E13*G13+F13*H13
A14: 7 | B14: =(A14-1)/2000*$C$2 | C14: =INDEX(Bits!$E$25:$E$124,INT(B14)+1) | D14: =MAX(1,MIN(INT(B14/$C$4)+1,$C$5)) | E14: =IF($C$5=0,0,INDEX(Symboles!$G$6:$G$101,D14)) | F14: =IF($C$5=0,0,INDEX(Symboles!$H$6:$H$101,D14)) | G14: =COS(2*PI()*$C$3*B14) | H14: =SIN(2*PI()*$C$3*B14) | I14: =E14*G14+F14*H14
A15: 8 | B15: =(A15-1)/2000*$C$2 | C15: =INDEX(Bits!$E$25:$E$124,INT(B15)+1) | D15: =MAX(1,MIN(INT(B15/$C$4)+1,$C$5)) | E15: =IF($C$5=0,0,INDEX(Symboles!$G$6:$G$101,D15)) | F15: =IF($C$5=0,0,INDEX(Symboles!$H$6:$H$101,D15)) | G15: =COS(2*PI()*$C$3*B15) | H15: =SIN(2*PI()*$C$3*B15) | I15: =E15*G15+F15*H15
A16: 9 | B16: =(A16-1)/2000*$C$2 | C16: =INDEX(Bits!$E$25:$E$124,INT(B16)+1) | D16: =MAX(1,MIN(INT(B16/$C$4)+1,$C$5)) | E16: =IF($C$5=0,0,INDEX(Symboles!$G$6:$G$101,D16)) | F16: =IF($C$5=0,0,INDEX(Symboles!$H$6:$H$101,D16)) | G16: =COS(2*PI()*$C$3*B16) | H16: =SIN(2*PI()*$C$3*B16) | I16: =E16*G16+F16*H16
A17: 10 | B17: =(A17-1)/2000*$C$2 | C17: =INDEX(Bits!$E$25:$E$124,INT(B17)+1) | D17: =MAX(1,MIN(INT(B17/$C$4)+1,$C$5)) | E17: =IF($C$5=0,0,INDEX(Symboles!$G$6:$G$101,D17)) | F17: =IF($C$5=0,0,INDEX(Symboles!$H$6:$H$101,D17)) | G17: =COS(2*PI()*$C$3*B17) | H17: =SIN(2*PI()*$C$3*B17) | I17: =E17*G17+F17*H17
A18: 11 | B18: =(A18-1)/2000*$C$2 | C18: =INDEX(Bits!$E$25:$E$124,INT(B18)+1) | D18: =MAX(1,MIN(INT(B18/$C$4)+1,$C$5)) | E18: =IF($C$5=0,0,INDEX(Symboles!$G$6:$G$101,D18)) | F18: =IF($C$5=0,0,INDEX(Symboles!$H$6:$H$101,D18)) | G18: =COS(2*PI()*$C$3*B18) | H18: =SIN(2*PI()*$C$3*B18) | I18: =E18*G18+F18*H18
A19: 12 | B19: =(A19-1)/2000*$C$2 | C19: =INDEX(Bits!$E$25:$E$124,INT(B19)+1) | D19: =MAX(1,MIN(INT(B19/$C$4)+1,$C$5)) | E19: =IF($C$5=0,0,INDEX(Symboles!$G$6:$G$101,D19)) | F19: =IF($C$5=0,0,INDEX(Symboles!$H$6:$H$101,D19)) | G19: =COS(2*PI()*$C$3*B19) | H19: =SIN(2*PI()*$C$3*B19) | I19: =E19*G19+F19*H19
... A2007: 2000 | B2007: =(A2007-1)/2000*$C$2 | C2007: =INDEX(Bits!$E$25:$E$124,INT(B2007)+1) | D2007: =MAX(1,MIN(INT(B2007/$C$4)+1,$C$5)) | E2007: =IF($C$5=0,0,INDEX(Symboles!$G$6:$G$101,D2007)) | F2007: =IF($C$5=0,0,INDEX(Symboles!$H$6:$H$101,D2007)) | G2007: =COS(2*PI()*$C$3*B2007) | H2007: =SIN(2*PI()*$C$3*B2007) | I2007: =E2007*G2007+F2007*H2007

Sheet Oeil
A1: Diagramme de l'œil — bande de base I(t) et Q(t) mise en forme
A2: Chaque trace = fenêtre de 2 symboles centrée sur un instant d'échantillonnage (x = 0). 16 éch./symbole, filtre tronqué à ±4 symboles, message répété de façon cyclique. 99 = trace inutilisée (hors graphique).
A3: Nb symboles N | B3: ='Tableau_de_bord'!C14 | D3: Filtres | E3: Rectangulaire (NRZ)
A4: N° filtre | B4: =MATCH('Tableau_de_bord'!L51,$E$3:$E$4,0) | E4: Cosinus surélevé
A5: Roll-off α | B5: ='Tableau_de_bord'!L52
A6: Bruit σ (par voie) | B6: ='Tableau_de_bord'!L53
P8: Voie I | DI8: Voie Q
A9: i | B9: x (en T) | C9: c_i | D9: r_i | E9: h(j=-4) | F9: h(j=-3) | G9: h(j=-2) | H9: h(j=-1) | I9: h(j=0) | J9: h(j=1) | K9: h(j=2) | L9: h(j=3) | M9: h(j=4) | P9: trace 1 | Q9: trace 2 | R9: trace 3 | S9: trace 4 | T9: trace 5 | U9: trace 6 | V9: trace 7 | W9: trace 8 | X9: trace 9 | Y9: trace 10 | Z9: trace 11 | AA9: trace 12 | AB9: trace 13 | AC9: trace 14 | AD9: trace 15 | AE9: trace 16 | AF9: trace 17 | AG9: trace 18 | AH9: trace 19 | AI9: trace 20 | AJ9: trace 21 | AK9: trace 22 | AL9: trace 23 | AM9: trace 24 | AN9: trace 25 | AO9: trace 26 | AP9: trace 27 | AQ9: trace 28 | AR9: trace 29 | AS9: trace 30 | AT9: trace 31 | AU9: trace 32 | AV9: trace 33 | AW9: trace 34 | AX9: trace 35 | AY9: trace 36 | AZ9: trace 37 | BA9: trace 38 | BB9: trace 39 | BC9: trace 40 | BD9: trace 41 | BE9: trace 42 | BF9: trace 43 | BG9: trace 44 | BH9: trace 45 | BI9: trace 46 | BJ9: trace 47 | BK9: trace 48 | BL9: trace 49 | BM9: trace 50 | BN9: trace 51 | BO9: trace 52 | BP9: trace 53 | BQ9: trace 54 | BR9: trace 55 | BS9: trace 56 | BT9: trace 57 | BU9: trace 58 | BV9: trace 59 | BW9: trace 60 | BX9: trace 61 | BY9: trace 62 | BZ9: trace 63 | CA9: trace 64 | CB9: trace 65 | CC9: trace 66 | CD9: trace 67 | CE9: trace 68 | CF9: trace 69 | CG9: trace 70 | CH9: trace 71 | CI9: trace 72 | CJ9: trace 73 | CK9: trace 74 | CL9: trace 75 | CM9: trace 76 | CN9: trace 77 | CO9: trace 78 | CP9: trace 79 | CQ9: trace 80 | CR9: trace 81 | CS9: trace 82 | CT9: trace 83 | CU9: trace 84 | CV9: trace 85 | CW9: trace 86 | CX9: trace 87 | CY9: trace 88 | CZ9: trace 89 | DA9: trace 90 | DB9: trace 91 | DC9: trace 92 | DD9: trace 93 | DE9: trace 94 | DF9: trace 95 | DG9: trace 96 | DI9: trace 1 | DJ9: trace 2 | DK9: trace 3 | DL9: trace 4 | DM9: trace 5 | DN9: trace 6 | DO9: trace 7 | DP9: trace 8 | DQ9: trace 9 | DR9: trace 10 | DS9: trace 11 | DT9: trace 12 | DU9: trace 13 | DV9: trace 14 | DW9: trace 15 | DX9: trace 16 | DY9: trace 17 | DZ9: trace 18 | EA9: trace 19 | EB9: trace 20 | EC9: trace 21 | ED9: trace 22 | EE9: trace 23 | EF9: trace 24 | EG9: trace 25 | EH9: trace 26 | EI9: trace 27 | EJ9: trace 28 | EK9: trace 29 | EL9: trace 30 | EM9: trace 31 | EN9: trace 32 | EO9: trace 33 | EP9: trace 34 | EQ9: trace 35 | ER9: trace 36 | ES9: trace 37 | ET9: trace 38 | EU9: trace 39 | EV9: trace 40 | EW9: trace 41 | EX9: trace 42 | EY9: trace 43 | EZ9: trace 44 | FA9: trace 45 | FB9: trace 46 | FC9: trace 47 | FD9: trace 48 | FE9: trace 49 | FF9: trace 50 | FG9: trace 51 | FH9: trace 52 | FI9: trace 53 | FJ9: trace 54 | FK9: trace 55 | FL9: trace 56 | FM9: trace 57 | FN9: trace 58 | FO9: trace 59 | FP9: trace 60 | FQ9: trace 61 | FR9: trace 62 | FS9: trace 63 | FT9: trace 64 | FU9: trace 65 | FV9: trace 66 | FW9: trace 67 | FX9: trace 68 | FY9: trace 69 | FZ9: trace 70 | GA9: trace 71 | GB9: trace 72 | GC9: trace 73 | GD9: trace 74 | GE9: trace 75 | GF9: trace 76 | GG9: trace 77 | GH9: trace 78 | GI9: trace 79 | GJ9: trace 80 | GK9: trace 81 | GL9: trace 82 | GM9: trace 83 | GN9: trace 84 | GO9: trace 85 | GP9: trace 86 | GQ9: trace 87 | GR9: trace 88 | GS9: trace 89 | GT9: trace 90 | GU9: trace 91 | GV9: trace 92 | GW9: trace 93 | GX9: trace 94 | GY9: trace 95 | GZ9: trace 96
